<?xml version="1.0" ?>
<!-- =================================================================================== -->
<!-- |    This document was autogenerated by xacro from variable_tilt_hexacopter.urdf.xacro | -->
<!-- |    EDITING THIS FILE BY HAND IS NOT RECOMMENDED                                 | -->
<!-- =================================================================================== -->
<robot name="variable_tilt_hexacopter">
  <!-- ======================
       0. Properties
  ====================== -->
  <!-- ======================
       1. Macros
  ====================== -->
  <!-- ======================
       2. Link Definitions
  ====================== -->
  <!-- Dummy Root -->
  <link name="base_dummy"/>
  <joint name="joint_base_dummy_to_base" type="fixed">
    <parent link="base_dummy"/>
    <child link="base"/>
    <origin xyz="0 0 0"/>
  </joint>
  <!-- Base -->
  <link name="base">
    <inertial>
      <mass value="1.564"/>
      <origin xyz="0 0 0"/>
      <inertia ixx="0.00229686" ixy="0" ixz="0" iyy="0.00229686" iyz="0" izz="0.00394206"/>
    </inertial>
    <visual>
      <geometry>
        <cylinder length="0.05" radius="0.071"/>
      </geometry>
    </visual>
    <collision>
      <geometry>
        <cylinder length="0.05" radius="0.071"/>
      </geometry>
    </collision>
  </link>
  <link name="gear_leg_left">
    <inertial>
      <mass value="0.1"/>
      <origin xyz="0 0 -0.05"/>
      <inertia ixx="0.0001" ixy="0" ixz="0" iyy="0.0001" iyz="0" izz="0.0001"/>
    </inertial>
    <visual>
      <origin xyz="0 0 -0.05"/>
      <geometry>
        <cylinder length="0.1" radius="0.01"/>
      </geometry>
    </visual>
    <collision>
      <origin xyz="0 0 -0.05"/>
      <geometry>
        <cylinder length="0.1" radius="0.01"/>
      </geometry>
    </collision>
  </link>
  <joint name="joint_gear_leg_left" type="fixed">
    <parent link="base"/>
    <child link="gear_leg_left"/>
    <origin xyz="0 0.05 0"/>
  </joint>
  <link name="gear_skid_left">
    <inertial>
      <mass value="0.1"/>
      <origin xyz="0 0 0"/>
      <inertia ixx="0.0001" ixy="0" ixz="0" iyy="0.0001" iyz="0" izz="0.0001"/>
    </inertial>
    <visual>
      <origin xyz="0 0 -0.1"/>
      <geometry>
        <box size="0.3 0.02 0.01"/>
      </geometry>
    </visual>
    <collision>
      <origin xyz="0 0 -0.1"/>
      <geometry>
        <box size="0.3 0.02 0.01"/>
      </geometry>
    </collision>
  </link>
  <joint name="joint_gear_skid_left" type="fixed">
    <parent link="gear_leg_left"/>
    <child link="gear_skid_left"/>
    <origin xyz="0 0 0"/>
  </joint>
  <link name="gear_leg_right">
    <inertial>
      <mass value="0.1"/>
      <origin xyz="0 0 -0.05"/>
      <inertia ixx="0.0001" ixy="0" ixz="0" iyy="0.0001" iyz="0" izz="0.0001"/>
    </inertial>
    <visual>
      <origin xyz="0 0 -0.05"/>
      <geometry>
        <cylinder length="0.1" radius="0.01"/>
      </geometry>
    </visual>
    <collision>
      <origin xyz="0 0 -0.05"/>
      <geometry>
        <cylinder length="0.1" radius="0.01"/>
      </geometry>
    </collision>
  </link>
  <joint name="joint_gear_leg_right" type="fixed">
    <parent link="base"/>
    <child link="gear_leg_right"/>
    <origin xyz="0 -0.05 0"/>
  </joint>
  <link name="gear_skid_right">
    <inertial>
      <mass value="0.1"/>
      <origin xyz="0 0 0"/>
      <inertia ixx="0.0001" ixy="0" ixz="0" iyy="0.0001" iyz="0" izz="0.0001"/>
    </inertial>
    <visual>
      <origin xyz="0 0 -0.1"/>
      <geometry>
        <box size="0.3 0.02 0.01"/>
      </geometry>
    </visual>
    <collision>
      <origin xyz="0 0 -0.1"/>
      <geometry>
        <box size="0.3 0.02 0.01"/>
      </geometry>
    </collision>
  </link>
  <joint name="joint_gear_skid_right" type="fixed">
    <parent link="gear_leg_right"/>
    <child link="gear_skid_right"/>
    <origin xyz="0 0 0"/>
  </joint>
  <link name="arm_1">
    <inertial>
      <mass value="0.16"/>
      <origin xyz="0.1145 0 0"/>
      <inertia ixx="0.000715213" ixy="0" ixz="0" iyy="0.000715213" iyz="0" izz="3.2e-05"/>
    </inertial>
    <visual>
      <origin rpy="0 1.5708 0" xyz="0 0 0"/>
      <geometry>
        <cylinder length="0.229" radius="0.02"/>
      </geometry>
    </visual>
    <collision>
      <origin rpy="0 1.5708 0" xyz="0 0 0"/>
      <geometry>
        <cylinder length="0.229" radius="0.02"/>
      </geometry>
    </collision>
  </link>
  <joint name="joint_arm_1" type="revolute">
    <parent link="base"/>
    <child link="arm_1"/>
    <origin rpy="0 0 0" xyz="0.1855 0 0"/>
    <axis xyz="1 0 0"/>
    <limit effort="5" lower="-1.57" upper="1.57" velocity="2.0"/>
  </joint>
  <link name="motor_1">
    <inertial>
      <mass value="0.088"/>
      <origin xyz="0 0 0"/>
      <inertia ixx="0.000112917" ixy="0" ixz="0" iyy="0.000112917" iyz="0" izz="6.25e-05"/>
    </inertial>
    <visual>
      <origin xyz="0 0 0"/>
      <geometry>
        <cylinder length="0.05" radius="0.02"/>
      </geometry>
    </visual>
    <collision>
      <origin xyz="0 0 0"/>
      <geometry>
        <cylinder length="0.05" radius="0.02"/>
      </geometry>
    </collision>
  </link>
  <joint name="joint_motor_1" type="fixed">
    <parent link="arm_1"/>
    <child link="motor_1"/>
    <origin xyz="0.0945 0 0.02"/>
  </joint>
  <link name="arm_2">
    <inertial>
      <mass value="0.16"/>
      <origin xyz="0.1145 0 0"/>
      <inertia ixx="0.000715213" ixy="0" ixz="0" iyy="0.000715213" iyz="0" izz="3.2e-05"/>
    </inertial>
    <visual>
      <origin rpy="0 1.5708 0" xyz="0 0 0"/>
      <geometry>
        <cylinder length="0.229" radius="0.02"/>
      </geometry>
    </visual>
    <collision>
      <origin rpy="0 1.5708 0" xyz="0 0 0"/>
      <geometry>
        <cylinder length="0.229" radius="0.02"/>
      </geometry>
    </collision>
  </link>
  <joint name="joint_arm_2" type="revolute">
    <parent link="base"/>
    <child link="arm_2"/>
    <origin rpy="0 0 1.047" xyz="0.09275 0.160643 0"/>
    <axis xyz="1 0 0"/>
    <limit effort="5" lower="-1.57" upper="1.57" velocity="2.0"/>
  </joint>
  <link name="motor_2">
    <inertial>
      <mass value="0.088"/>
      <origin xyz="0 0 0"/>
      <inertia ixx="0.000112917" ixy="0" ixz="0" iyy="0.000112917" iyz="0" izz="6.25e-05"/>
    </inertial>
    <visual>
      <origin xyz="0 0 0"/>
      <geometry>
        <cylinder length="0.05" radius="0.02"/>
      </geometry>
    </visual>
    <collision>
      <origin xyz="0 0 0"/>
      <geometry>
        <cylinder length="0.05" radius="0.02"/>
      </geometry>
    </collision>
  </link>
  <joint name="joint_motor_2" type="fixed">
    <parent link="arm_2"/>
    <child link="motor_2"/>
    <origin xyz="0.0945 0 0.02"/>
  </joint>
  <link name="arm_3">
    <inertial>
      <mass value="0.16"/>
      <origin xyz="0.1145 0 0"/>
      <inertia ixx="0.000715213" ixy="0" ixz="0" iyy="0.000715213" iyz="0" izz="3.2e-05"/>
    </inertial>
    <visual>
      <origin rpy="0 1.5708 0" xyz="0 0 0"/>
      <geometry>
        <cylinder length="0.229" radius="0.02"/>
      </geometry>
    </visual>
    <collision>
      <origin rpy="0 1.5708 0" xyz="0 0 0"/>
      <geometry>
        <cylinder length="0.229" radius="0.02"/>
      </geometry>
    </collision>
  </link>
  <joint name="joint_arm_3" type="revolute">
    <parent link="base"/>
    <child link="arm_3"/>
    <origin rpy="0 0 2.094" xyz="-0.09275 0.160643 0"/>
    <axis xyz="1 0 0"/>
    <limit effort="5" lower="-1.57" upper="1.57" velocity="2.0"/>
  </joint>
  <link name="motor_3">
    <inertial>
      <mass value="0.088"/>
      <origin xyz="0 0 0"/>
      <inertia ixx="0.000112917" ixy="0" ixz="0" iyy="0.000112917" iyz="0" izz="6.25e-05"/>
    </inertial>
    <visual>
      <origin xyz="0 0 0"/>
      <geometry>
        <cylinder length="0.05" radius="0.02"/>
      </geometry>
    </visual>
    <collision>
      <origin xyz="0 0 0"/>
      <geometry>
        <cylinder length="0.05" radius="0.02"/>
      </geometry>
    </collision>
  </link>
  <joint name="joint_motor_3" type="fixed">
    <parent link="arm_3"/>
    <child link="motor_3"/>
    <origin xyz="0.0945 0 0.02"/>
  </joint>
  <link name="arm_4">
    <inertial>
      <mass value="0.16"/>
      <origin xyz="0.1145 0 0"/>
      <inertia ixx="0.000715213" ixy="0" ixz="0" iyy="0.000715213" iyz="0" izz="3.2e-05"/>
    </inertial>
    <visual>
      <origin rpy="0 1.5708 0" xyz="0 0 0"/>
      <geometry>
        <cylinder length="0.229" radius="0.02"/>
      </geometry>
    </visual>
    <collision>
      <origin rpy="0 1.5708 0" xyz="0 0 0"/>
      <geometry>
        <cylinder length="0.229" radius="0.02"/>
      </geometry>
    </collision>
  </link>
  <joint name="joint_arm_4" type="revolute">
    <parent link="base"/>
    <child link="arm_4"/>
    <origin rpy="0 0 3.141" xyz="-0.1855 0 0"/>
    <axis xyz="1 0 0"/>
    <limit effort="5" lower="-1.57" upper="1.57" velocity="2.0"/>
  </joint>
  <link name="motor_4">
    <inertial>
      <mass value="0.088"/>
      <origin xyz="0 0 0"/>
      <inertia ixx="0.000112917" ixy="0" ixz="0" iyy="0.000112917" iyz="0" izz="6.25e-05"/>
    </inertial>
    <visual>
      <origin xyz="0 0 0"/>
      <geometry>
        <cylinder length="0.05" radius="0.02"/>
      </geometry>
    </visual>
    <collision>
      <origin xyz="0 0 0"/>
      <geometry>
        <cylinder length="0.05" radius="0.02"/>
      </geometry>
    </collision>
  </link>
  <joint name="joint_motor_4" type="fixed">
    <parent link="arm_4"/>
    <child link="motor_4"/>
    <origin xyz="0.0945 0 0.02"/>
  </joint>
  <link name="arm_5">
    <inertial>
      <mass value="0.16"/>
      <origin xyz="0.1145 0 0"/>
      <inertia ixx="0.000715213" ixy="0" ixz="0" iyy="0.000715213" iyz="0" izz="3.2e-05"/>
    </inertial>
    <visual>
      <origin rpy="0 1.5708 0" xyz="0 0 0"/>
      <geometry>
        <cylinder length="0.229" radius="0.02"/>
      </geometry>
    </visual>
    <collision>
      <origin rpy="0 1.5708 0" xyz="0 0 0"/>
      <geometry>
        <cylinder length="0.229" radius="0.02"/>
      </geometry>
    </collision>
  </link>
  <joint name="joint_arm_5" type="revolute">
    <parent link="base"/>
    <child link="arm_5"/>
    <origin rpy="0 0 4.188" xyz="-0.09275 -0.160643 0"/>
    <axis xyz="1 0 0"/>
    <limit effort="5" lower="-1.57" upper="1.57" velocity="2.0"/>
  </joint>
  <link name="motor_5">
    <inertial>
      <mass value="0.088"/>
      <origin xyz="0 0 0"/>
      <inertia ixx="0.000112917" ixy="0" ixz="0" iyy="0.000112917" iyz="0" izz="6.25e-05"/>
    </inertial>
    <visual>
      <origin xyz="0 0 0"/>
      <geometry>
        <cylinder length="0.05" radius="0.02"/>
      </geometry>
    </visual>
    <collision>
      <origin xyz="0 0 0"/>
      <geometry>
        <cylinder length="0.05" radius="0.02"/>
      </geometry>
    </collision>
  </link>
  <joint name="joint_motor_5" type="fixed">
    <parent link="arm_5"/>
    <child link="motor_5"/>
    <origin xyz="0.0945 0 0.02"/>
  </joint>
  <link name="arm_6">
    <inertial>
      <mass value="0.16"/>
      <origin xyz="0.1145 0 0"/>
      <inertia ixx="0.000715213" ixy="0" ixz="0" iyy="0.000715213" iyz="0" izz="3.2e-05"/>
    </inertial>
    <visual>
      <origin rpy="0 1.5708 0" xyz="0 0 0"/>
      <geometry>
        <cylinder length="0.229" radius="0.02"/>
      </geometry>
    </visual>
    <collision>
      <origin rpy="0 1.5708 0" xyz="0 0 0"/>
      <geometry>
        <cylinder length="0.229" radius="0.02"/>
      </geometry>
    </collision>
  </link>
  <joint name="joint_arm_6" type="revolute">
    <parent link="base"/>
    <child link="arm_6"/>
    <origin rpy="0 0 5.235" xyz="0.09275 -0.160643 0"/>
    <axis xyz="1 0 0"/>
    <limit effort="5" lower="-1.57" upper="1.57" velocity="2.0"/>
  </joint>
  <link name="motor_6">
    <inertial>
      <mass value="0.088"/>
      <origin xyz="0 0 0"/>
      <inertia ixx="0.000112917" ixy="0" ixz="0" iyy="0.000112917" iyz="0" izz="6.25e-05"/>
    </inertial>
    <visual>
      <origin xyz="0 0 0"/>
      <geometry>
        <cylinder length="0.05" radius="0.02"/>
      </geometry>
    </visual>
    <collision>
      <origin xyz="0 0 0"/>
      <geometry>
        <cylinder length="0.05" radius="0.02"/>
      </geometry>
    </collision>
  </link>
  <joint name="joint_motor_6" type="fixed">
    <parent link="arm_6"/>
    <child link="motor_6"/>
    <origin xyz="0.0945 0 0.02"/>
  </joint>
  <link name="prop_1">
    <inertial>
      <mass value="0.024"/>
      <origin xyz="0 0 0.02"/>
      <inertia ixx="4.25e-06" ixy="0" ixz="0" iyy="0.00010145" iyz="0" izz="0.0001053"/>
    </inertial>
    <visual>
      <origin xyz="0 0 0.02"/>
      <geometry>
        <box size="0.225 0.02 0.01"/>
      </geometry>
    </visual>
    <collision>
      <origin xyz="0 0 0.02"/>
      <geometry>
        <box size="0.225 0.02 0.01"/>
      </geometry>
    </collision>
  </link>
  <joint name="joint_prop_1" type="continuous">
    <parent link="motor_1"/>
    <child link="prop_1"/>
    <axis xyz="0 0 1"/>
  </joint>
  <link name="prop_2">
    <inertial>
      <mass value="0.024"/>
      <origin xyz="0 0 0.02"/>
      <inertia ixx="4.25e-06" ixy="0" ixz="0" iyy="0.00010145" iyz="0" izz="0.0001053"/>
    </inertial>
    <visual>
      <origin xyz="0 0 0.02"/>
      <geometry>
        <box size="0.225 0.02 0.01"/>
      </geometry>
    </visual>
    <collision>
      <origin xyz="0 0 0.02"/>
      <geometry>
        <box size="0.225 0.02 0.01"/>
      </geometry>
    </collision>
  </link>
  <joint name="joint_prop_2" type="continuous">
    <parent link="motor_2"/>
    <child link="prop_2"/>
    <axis xyz="0 0 1"/>
  </joint>
  <link name="prop_3">
    <inertial>
      <mass value="0.024"/>
      <origin xyz="0 0 0.02"/>
      <inertia ixx="4.25e-06" ixy="0" ixz="0" iyy="0.00010145" iyz="0" izz="0.0001053"/>
    </inertial>
    <visual>
      <origin xyz="0 0 0.02"/>
      <geometry>
        <box size="0.225 0.02 0.01"/>
      </geometry>
    </visual>
    <collision>
      <origin xyz="0 0 0.02"/>
      <geometry>
        <box size="0.225 0.02 0.01"/>
      </geometry>
    </collision>
  </link>
  <joint name="joint_prop_3" type="continuous">
    <parent link="motor_3"/>
    <child link="prop_3"/>
    <axis xyz="0 0 1"/>
  </joint>
  <link name="prop_4">
    <inertial>
      <mass value="0.024"/>
      <origin xyz="0 0 0.02"/>
      <inertia ixx="4.25e-06" ixy="0" ixz="0" iyy="0.00010145" iyz="0" izz="0.0001053"/>
    </inertial>
    <visual>
      <origin xyz="0 0 0.02"/>
      <geometry>
        <box size="0.225 0.02 0.01"/>
      </geometry>
    </visual>
    <collision>
      <origin xyz="0 0 0.02"/>
      <geometry>
        <box size="0.225 0.02 0.01"/>
      </geometry>
    </collision>
  </link>
  <joint name="joint_prop_4" type="continuous">
    <parent link="motor_4"/>
    <child link="prop_4"/>
    <axis xyz="0 0 1"/>
  </joint>
  <link name="prop_5">
    <inertial>
      <mass value="0.024"/>
      <origin xyz="0 0 0.02"/>
      <inertia ixx="4.25e-06" ixy="0" ixz="0" iyy="0.00010145" iyz="0" izz="0.0001053"/>
    </inertial>
    <visual>
      <origin xyz="0 0 0.02"/>
      <geometry>
        <box size="0.225 0.02 0.01"/>
      </geometry>
    </visual>
    <collision>
      <origin xyz="0 0 0.02"/>
      <geometry>
        <box size="0.225 0.02 0.01"/>
      </geometry>
    </collision>
  </link>
  <joint name="joint_prop_5" type="continuous">
    <parent link="motor_5"/>
    <child link="prop_5"/>
    <axis xyz="0 0 1"/>
  </joint>
  <link name="prop_6">
    <inertial>
      <mass value="0.024"/>
      <origin xyz="0 0 0.02"/>
      <inertia ixx="4.25e-06" ixy="0" ixz="0" iyy="0.00010145" iyz="0" izz="0.0001053"/>
    </inertial>
    <visual>
      <origin xyz="0 0 0.02"/>
      <geometry>
        <box size="0.225 0.02 0.01"/>
      </geometry>
    </visual>
    <collision>
      <origin xyz="0 0 0.02"/>
      <geometry>
        <box size="0.225 0.02 0.01"/>
      </geometry>
    </collision>
  </link>
  <joint name="joint_prop_6" type="continuous">
    <parent link="motor_6"/>
    <child link="prop_6"/>
    <axis xyz="0 0 1"/>
  </joint>
  <!-- Pluggins -->
  <!-- Pose Publisher Plugin -->
  <plugin filename="ignition-gazebo-pose-publisher-system" name="ignition::gazebo::systems::PosePublisher">
    <publish_link_pose>true</publish_link_pose>
    <publish_sensor_pose>true</publish_sensor_pose>
  </plugin>
  <!-- Joint states plugin -->
  <plugin filename="ignition-gazebo-joint-state-publisher-system" name="ignition::gazebo::systems::JointStatePublisher">
    <robotNamespace>/model/variable_tilt_hexacopter</robotNamespace>
  </plugin>
  <!-- IMU Plugin -->
  <plugin filename="ignition-gazebo-imu-system" name="ignition::gazebo::systems::Imu">
    <topic>/hexacopter/imu</topic>
    <link_name>base</link_name>
  </plugin>
  <!-- Odometry Plugin -->
  <plugin filename="ignition-gazebo-odometry-publisher-system" name="ignition::gazebo::systems::OdometryPublisher">
    <topic>/hexacopter/odom</topic>
  </plugin>
  <!-- ========== Sub-macros ========== -->
  <!-- ========== Plugin Instantiations ========== -->
  <plugin filename="libignition-gazebo-multicopter-motor-model-system" name="ignition::gazebo::systems::MulticopterMotorModel">
    <jointName>joint_prop_1</jointName>
    <linkName>prop_1</linkName>
    <turningDirection>ccw</turningDirection>
    <timeConstantUp>0.0125</timeConstantUp>
    <timeConstantDown>0.025</timeConstantDown>
    <maxRotVelocity>800.0</maxRotVelocity>
    <motorConstant>8.54858e-06</motorConstant>
    <momentConstant>0.016</momentConstant>
    <commandSubTopic>command/motor_speed</commandSubTopic>
    <motorNumber>1</motorNumber>
    <rotorDragCoefficient>8.06428e-05</rotorDragCoefficient>
    <rollingMomentCoefficient>1e-06</rollingMomentCoefficient>
    <motorSpeedPubTopic>motor_speed/1</motorSpeedPubTopic>
    <rotorVelocitySlowdownSim>10</rotorVelocitySlowdownSim>
    <motorType>velocity</motorType>
  </plugin>
  <plugin filename="libignition-gazebo-multicopter-motor-model-system" name="ignition::gazebo::systems::MulticopterMotorModel">
    <jointName>joint_prop_2</jointName>
    <linkName>prop_2</linkName>
    <turningDirection>cw</turningDirection>
    <timeConstantUp>0.0125</timeConstantUp>
    <timeConstantDown>0.025</timeConstantDown>
    <maxRotVelocity>800.0</maxRotVelocity>
    <motorConstant>8.54858e-06</motorConstant>
    <momentConstant>0.016</momentConstant>
    <commandSubTopic>command/motor_speed</commandSubTopic>
    <motorNumber>2</motorNumber>
    <rotorDragCoefficient>8.06428e-05</rotorDragCoefficient>
    <rollingMomentCoefficient>1e-06</rollingMomentCoefficient>
    <motorSpeedPubTopic>motor_speed/2</motorSpeedPubTopic>
    <rotorVelocitySlowdownSim>10</rotorVelocitySlowdownSim>
    <motorType>velocity</motorType>
  </plugin>
  <plugin filename="libignition-gazebo-multicopter-motor-model-system" name="ignition::gazebo::systems::MulticopterMotorModel">
    <jointName>joint_prop_3</jointName>
    <linkName>prop_3</linkName>
    <turningDirection>ccw</turningDirection>
    <timeConstantUp>0.0125</timeConstantUp>
    <timeConstantDown>0.025</timeConstantDown>
    <maxRotVelocity>800.0</maxRotVelocity>
    <motorConstant>8.54858e-06</motorConstant>
    <momentConstant>0.016</momentConstant>
    <commandSubTopic>command/motor_speed</commandSubTopic>
    <motorNumber>3</motorNumber>
    <rotorDragCoefficient>8.06428e-05</rotorDragCoefficient>
    <rollingMomentCoefficient>1e-06</rollingMomentCoefficient>
    <motorSpeedPubTopic>motor_speed/3</motorSpeedPubTopic>
    <rotorVelocitySlowdownSim>10</rotorVelocitySlowdownSim>
    <motorType>velocity</motorType>
  </plugin>
  <plugin filename="libignition-gazebo-multicopter-motor-model-system" name="ignition::gazebo::systems::MulticopterMotorModel">
    <jointName>joint_prop_4</jointName>
    <linkName>prop_4</linkName>
    <turningDirection>cw</turningDirection>
    <timeConstantUp>0.0125</timeConstantUp>
    <timeConstantDown>0.025</timeConstantDown>
    <maxRotVelocity>800.0</maxRotVelocity>
    <motorConstant>8.54858e-06</motorConstant>
    <momentConstant>0.016</momentConstant>
    <commandSubTopic>command/motor_speed</commandSubTopic>
    <motorNumber>4</motorNumber>
    <rotorDragCoefficient>8.06428e-05</rotorDragCoefficient>
    <rollingMomentCoefficient>1e-06</rollingMomentCoefficient>
    <motorSpeedPubTopic>motor_speed/4</motorSpeedPubTopic>
    <rotorVelocitySlowdownSim>10</rotorVelocitySlowdownSim>
    <motorType>velocity</motorType>
  </plugin>
  <plugin filename="libignition-gazebo-multicopter-motor-model-system" name="ignition::gazebo::systems::MulticopterMotorModel">
    <jointName>joint_prop_5</jointName>
    <linkName>prop_5</linkName>
    <turningDirection>ccw</turningDirection>
    <timeConstantUp>0.0125</timeConstantUp>
    <timeConstantDown>0.025</timeConstantDown>
    <maxRotVelocity>800.0</maxRotVelocity>
    <motorConstant>8.54858e-06</motorConstant>
    <momentConstant>0.016</momentConstant>
    <commandSubTopic>command/motor_speed</commandSubTopic>
    <motorNumber>5</motorNumber>
    <rotorDragCoefficient>8.06428e-05</rotorDragCoefficient>
    <rollingMomentCoefficient>1e-06</rollingMomentCoefficient>
    <motorSpeedPubTopic>motor_speed/5</motorSpeedPubTopic>
    <rotorVelocitySlowdownSim>10</rotorVelocitySlowdownSim>
    <motorType>velocity</motorType>
  </plugin>
  <plugin filename="libignition-gazebo-multicopter-motor-model-system" name="ignition::gazebo::systems::MulticopterMotorModel">
    <jointName>joint_prop_6</jointName>
    <linkName>prop_6</linkName>
    <turningDirection>cw</turningDirection>
    <timeConstantUp>0.0125</timeConstantUp>
    <timeConstantDown>0.025</timeConstantDown>
    <maxRotVelocity>800.0</maxRotVelocity>
    <motorConstant>8.54858e-06</motorConstant>
    <momentConstant>0.016</momentConstant>
    <commandSubTopic>command/motor_speed</commandSubTopic>
    <motorNumber>6</motorNumber>
    <rotorDragCoefficient>8.06428e-05</rotorDragCoefficient>
    <rollingMomentCoefficient>1e-06</rollingMomentCoefficient>
    <motorSpeedPubTopic>motor_speed/6</motorSpeedPubTopic>
    <rotorVelocitySlowdownSim>10</rotorVelocitySlowdownSim>
    <motorType>velocity</motorType>
  </plugin>
  <plugin filename="libignition-gazebo-lift-drag-system" name="ignition::gazebo::systems::LiftDrag">
    <a0>0.2</a0>
    <cla>10.0</cla>
    <cda>0.0001</cda>
    <cma>0.00</cma>
    <alpha_stall>10.0</alpha_stall>
    <cla_stall>1.0</cla_stall>
    <cda_stall>0.001</cda_stall>
    <cma_stall>0.0</cma_stall>
    <cp>0.1125 0 0</cp>
    <area>0.0045000000000000005</area>
    <air_density>1.2041</air_density>
    <forward>0 0 -1</forward>
    <upward>0.0 1.0 0</upward>
    <link_name>prop_1</link_name>
  </plugin>
  <plugin filename="libignition-gazebo-lift-drag-system" name="ignition::gazebo::systems::LiftDrag">
    <a0>0.2</a0>
    <cla>10.0</cla>
    <cda>0.0001</cda>
    <cma>0.00</cma>
    <alpha_stall>10.0</alpha_stall>
    <cla_stall>1.0</cla_stall>
    <cda_stall>0.001</cda_stall>
    <cma_stall>0.0</cma_stall>
    <cp>0.1125 0 0</cp>
    <area>0.0045000000000000005</area>
    <air_density>1.2041</air_density>
    <forward>0 0 -1</forward>
    <upward>0.866 -0.5 0</upward>
    <link_name>prop_2</link_name>
  </plugin>
  <plugin filename="libignition-gazebo-lift-drag-system" name="ignition::gazebo::systems::LiftDrag">
    <a0>0.2</a0>
    <cla>10.0</cla>
    <cda>0.0001</cda>
    <cma>0.00</cma>
    <alpha_stall>10.0</alpha_stall>
    <cla_stall>1.0</cla_stall>
    <cda_stall>0.001</cda_stall>
    <cma_stall>0.0</cma_stall>
    <cp>0.1125 0 0</cp>
    <area>0.0045000000000000005</area>
    <air_density>1.2041</air_density>
    <forward>0 0 -1</forward>
    <upward>-0.866 -0.5 0</upward>
    <link_name>prop_3</link_name>
  </plugin>
  <plugin filename="libignition-gazebo-lift-drag-system" name="ignition::gazebo::systems::LiftDrag">
    <a0>0.2</a0>
    <cla>10.0</cla>
    <cda>0.0001</cda>
    <cma>0.00</cma>
    <alpha_stall>10.0</alpha_stall>
    <cla_stall>1.0</cla_stall>
    <cda_stall>0.001</cda_stall>
    <cma_stall>0.0</cma_stall>
    <cp>0.1125 0 0</cp>
    <area>0.0045000000000000005</area>
    <air_density>1.2041</air_density>
    <forward>0 0 -1</forward>
    <upward>0.0 -1.0 0</upward>
    <link_name>prop_4</link_name>
  </plugin>
  <plugin filename="libignition-gazebo-lift-drag-system" name="ignition::gazebo::systems::LiftDrag">
    <a0>0.2</a0>
    <cla>10.0</cla>
    <cda>0.0001</cda>
    <cma>0.00</cma>
    <alpha_stall>10.0</alpha_stall>
    <cla_stall>1.0</cla_stall>
    <cda_stall>0.001</cda_stall>
    <cma_stall>0.0</cma_stall>
    <cp>0.1125 0 0</cp>
    <area>0.0045000000000000005</area>
    <air_density>1.2041</air_density>
    <forward>0 0 -1</forward>
    <upward>0.866 0.5 0</upward>
    <link_name>prop_5</link_name>
  </plugin>
  <plugin filename="libignition-gazebo-lift-drag-system" name="ignition::gazebo::systems::LiftDrag">
    <a0>0.2</a0>
    <cla>10.0</cla>
    <cda>0.0001</cda>
    <cma>0.00</cma>
    <alpha_stall>10.0</alpha_stall>
    <cla_stall>1.0</cla_stall>
    <cda_stall>0.001</cda_stall>
    <cma_stall>0.0</cma_stall>
    <cp>0.1125 0 0</cp>
    <area>0.0045000000000000005</area>
    <air_density>1.2041</air_density>
    <forward>0 0 -1</forward>
    <upward>-0.866 0.5 0</upward>
    <link_name>prop_6</link_name>
  </plugin>
  <plugin filename="libignition-gazebo-joint-controller-system" name="ignition::gazebo::systems::JointController">
    <joint_name>joint_arm_1</joint_name>
    <use_force_commands>false</use_force_commands>
  </plugin>
  <plugin filename="libignition-gazebo-joint-controller-system" name="ignition::gazebo::systems::JointController">
    <joint_name>joint_arm_2</joint_name>
    <use_force_commands>false</use_force_commands>
  </plugin>
  <plugin filename="libignition-gazebo-joint-controller-system" name="ignition::gazebo::systems::JointController">
    <joint_name>joint_arm_3</joint_name>
    <use_force_commands>false</use_force_commands>
  </plugin>
  <plugin filename="libignition-gazebo-joint-controller-system" name="ignition::gazebo::systems::JointController">
    <joint_name>joint_arm_4</joint_name>
    <use_force_commands>false</use_force_commands>
  </plugin>
  <plugin filename="libignition-gazebo-joint-controller-system" name="ignition::gazebo::systems::JointController">
    <joint_name>joint_arm_5</joint_name>
    <use_force_commands>false</use_force_commands>
  </plugin>
  <plugin filename="libignition-gazebo-joint-controller-system" name="ignition::gazebo::systems::JointController">
    <joint_name>joint_arm_6</joint_name>
    <use_force_commands>false</use_force_commands>
  </plugin>
</robot>
